[2025-10-31T19:07:14.119723] subject=Byzantine Empire
Traceback (most recent call last):
  File "/Users/muhammedsaeed/anaconda3/envs/KB/lib/python3.11/site-packages/urllib3/response.py", line 779, in _error_catcher
    yield
  File "/Users/muhammedsaeed/anaconda3/envs/KB/lib/python3.11/site-packages/urllib3/response.py", line 1248, in read_chunked
    self._update_chunk_length()
  File "/Users/muhammedsaeed/anaconda3/envs/KB/lib/python3.11/site-packages/urllib3/response.py", line 1167, in _update_chunk_length
    line = self._fp.fp.readline()  # type: ignore[union-attr]
           ^^^^^^^^^^^^^^^^^^^^^^
  File "/Users/muhammedsaeed/anaconda3/envs/KB/lib/python3.11/socket.py", line 718, in readinto
    return self._sock.recv_into(b)
           ^^^^^^^^^^^^^^^^^^^^^^^
  File "/Users/muhammedsaeed/anaconda3/envs/KB/lib/python3.11/ssl.py", line 1314, in recv_into
    return self.read(nbytes, buffer)
           ^^^^^^^^^^^^^^^^^^^^^^^^^
  File "/Users/muhammedsaeed/anaconda3/envs/KB/lib/python3.11/ssl.py", line 1166, in read
    return self._sslobj.read(len, buffer)
           ^^^^^^^^^^^^^^^^^^^^^^^^^^^^^^
TimeoutError: The read operation timed out

The above exception was the direct cause of the following exception:

Traceback (most recent call last):
  File "/Users/muhammedsaeed/anaconda3/envs/KB/lib/python3.11/site-packages/requests/models.py", line 820, in generate
    yield from self.raw.stream(chunk_size, decode_content=True)
  File "/Users/muhammedsaeed/anaconda3/envs/KB/lib/python3.11/site-packages/urllib3/response.py", line 1088, in stream
    yield from self.read_chunked(amt, decode_content=decode_content)
  File "/Users/muhammedsaeed/anaconda3/envs/KB/lib/python3.11/site-packages/urllib3/response.py", line 1231, in read_chunked
    with self._error_catcher():
  File "/Users/muhammedsaeed/anaconda3/envs/KB/lib/python3.11/contextlib.py", line 158, in __exit__
    self.gen.throw(typ, value, traceback)
  File "/Users/muhammedsaeed/anaconda3/envs/KB/lib/python3.11/site-packages/urllib3/response.py", line 784, in _error_catcher
    raise ReadTimeoutError(self._pool, None, "Read timed out.") from e  # type: ignore[arg-type]
    ^^^^^^^^^^^^^^^^^^^^^^^^^^^^^^^^^^^^^^^^^^^^^^^^^^^^^^^^^^^^^^^^^^
urllib3.exceptions.ReadTimeoutError: HTTPSConnectionPool(host='api.deepseek.com', port=443): Read timed out.

During handling of the above exception, another exception occurred:

Traceback (most recent call last):
  File "/Users/muhammedsaeed/Downloads/TU Dresden/GPTKB_Hallucinations/crawler_simple.py", line 314, in main
    resp = el_llm(el_messages, json_schema=el_schema)
           ^^^^^^^^^^^^^^^^^^^^^^^^^^^^^^^^^^^^^^^^^^
  File "/Users/muhammedsaeed/Downloads/TU Dresden/GPTKB_Hallucinations/llm/factory.py", line 118, in _gen
    return client.generate(
           ^^^^^^^^^^^^^^^^
  File "/Users/muhammedsaeed/Downloads/TU Dresden/GPTKB_Hallucinations/llm/deepseek_client.py", line 81, in generate
    response = requests.post(url, headers=headers, json=body, timeout=90.0)
               ^^^^^^^^^^^^^^^^^^^^^^^^^^^^^^^^^^^^^^^^^^^^^^^^^^^^^^^^^^^^
  File "/Users/muhammedsaeed/anaconda3/envs/KB/lib/python3.11/site-packages/requests/api.py", line 115, in post
    return request("post", url, data=data, json=json, **kwargs)
           ^^^^^^^^^^^^^^^^^^^^^^^^^^^^^^^^^^^^^^^^^^^^^^^^^^^^
  File "/Users/muhammedsaeed/anaconda3/envs/KB/lib/python3.11/site-packages/requests/api.py", line 59, in request
    return session.request(method=method, url=url, **kwargs)
           ^^^^^^^^^^^^^^^^^^^^^^^^^^^^^^^^^^^^^^^^^^^^^^^^^
  File "/Users/muhammedsaeed/anaconda3/envs/KB/lib/python3.11/site-packages/requests/sessions.py", line 589, in request
    resp = self.send(prep, **send_kwargs)
           ^^^^^^^^^^^^^^^^^^^^^^^^^^^^^^
  File "/Users/muhammedsaeed/anaconda3/envs/KB/lib/python3.11/site-packages/requests/sessions.py", line 746, in send
    r.content
  File "/Users/muhammedsaeed/anaconda3/envs/KB/lib/python3.11/site-packages/requests/models.py", line 902, in content
    self._content = b"".join(self.iter_content(CONTENT_CHUNK_SIZE)) or b""
                    ^^^^^^^^^^^^^^^^^^^^^^^^^^^^^^^^^^^^^^^^^^^^^^^
  File "/Users/muhammedsaeed/anaconda3/envs/KB/lib/python3.11/site-packages/requests/models.py", line 826, in generate
    raise ConnectionError(e)
requests.exceptions.ConnectionError: HTTPSConnectionPool(host='api.deepseek.com', port=443): Read timed out.

[2025-10-31T19:36:51.763443] subject=Byzantine Empire
Traceback (most recent call last):
  File "/Users/muhammedsaeed/anaconda3/envs/KB/lib/python3.11/site-packages/urllib3/response.py", line 779, in _error_catcher
    yield
  File "/Users/muhammedsaeed/anaconda3/envs/KB/lib/python3.11/site-packages/urllib3/response.py", line 1248, in read_chunked
    self._update_chunk_length()
  File "/Users/muhammedsaeed/anaconda3/envs/KB/lib/python3.11/site-packages/urllib3/response.py", line 1167, in _update_chunk_length
    line = self._fp.fp.readline()  # type: ignore[union-attr]
           ^^^^^^^^^^^^^^^^^^^^^^
  File "/Users/muhammedsaeed/anaconda3/envs/KB/lib/python3.11/socket.py", line 718, in readinto
    return self._sock.recv_into(b)
           ^^^^^^^^^^^^^^^^^^^^^^^
  File "/Users/muhammedsaeed/anaconda3/envs/KB/lib/python3.11/ssl.py", line 1314, in recv_into
    return self.read(nbytes, buffer)
           ^^^^^^^^^^^^^^^^^^^^^^^^^
  File "/Users/muhammedsaeed/anaconda3/envs/KB/lib/python3.11/ssl.py", line 1166, in read
    return self._sslobj.read(len, buffer)
           ^^^^^^^^^^^^^^^^^^^^^^^^^^^^^^
TimeoutError: The read operation timed out

The above exception was the direct cause of the following exception:

Traceback (most recent call last):
  File "/Users/muhammedsaeed/anaconda3/envs/KB/lib/python3.11/site-packages/requests/models.py", line 820, in generate
    yield from self.raw.stream(chunk_size, decode_content=True)
  File "/Users/muhammedsaeed/anaconda3/envs/KB/lib/python3.11/site-packages/urllib3/response.py", line 1088, in stream
    yield from self.read_chunked(amt, decode_content=decode_content)
  File "/Users/muhammedsaeed/anaconda3/envs/KB/lib/python3.11/site-packages/urllib3/response.py", line 1231, in read_chunked
    with self._error_catcher():
  File "/Users/muhammedsaeed/anaconda3/envs/KB/lib/python3.11/contextlib.py", line 158, in __exit__
    self.gen.throw(typ, value, traceback)
  File "/Users/muhammedsaeed/anaconda3/envs/KB/lib/python3.11/site-packages/urllib3/response.py", line 784, in _error_catcher
    raise ReadTimeoutError(self._pool, None, "Read timed out.") from e  # type: ignore[arg-type]
    ^^^^^^^^^^^^^^^^^^^^^^^^^^^^^^^^^^^^^^^^^^^^^^^^^^^^^^^^^^^^^^^^^^
urllib3.exceptions.ReadTimeoutError: HTTPSConnectionPool(host='api.deepseek.com', port=443): Read timed out.

During handling of the above exception, another exception occurred:

Traceback (most recent call last):
  File "/Users/muhammedsaeed/Downloads/TU Dresden/GPTKB_Hallucinations/crawler_simple.py", line 314, in main
    resp = el_llm(el_messages, json_schema=el_schema)
           ^^^^^^^^^^^^^^^^^^^^^^^^^^^^^^^^^^^^^^^^^^
  File "/Users/muhammedsaeed/Downloads/TU Dresden/GPTKB_Hallucinations/llm/factory.py", line 118, in _gen
    return client.generate(
           ^^^^^^^^^^^^^^^^
  File "/Users/muhammedsaeed/Downloads/TU Dresden/GPTKB_Hallucinations/llm/deepseek_client.py", line 81, in generate
    response = requests.post(url, headers=headers, json=body, timeout=90.0)
               ^^^^^^^^^^^^^^^^^^^^^^^^^^^^^^^^^^^^^^^^^^^^^^^^^^^^^^^^^^^^
  File "/Users/muhammedsaeed/anaconda3/envs/KB/lib/python3.11/site-packages/requests/api.py", line 115, in post
    return request("post", url, data=data, json=json, **kwargs)
           ^^^^^^^^^^^^^^^^^^^^^^^^^^^^^^^^^^^^^^^^^^^^^^^^^^^^
  File "/Users/muhammedsaeed/anaconda3/envs/KB/lib/python3.11/site-packages/requests/api.py", line 59, in request
    return session.request(method=method, url=url, **kwargs)
           ^^^^^^^^^^^^^^^^^^^^^^^^^^^^^^^^^^^^^^^^^^^^^^^^^
  File "/Users/muhammedsaeed/anaconda3/envs/KB/lib/python3.11/site-packages/requests/sessions.py", line 589, in request
    resp = self.send(prep, **send_kwargs)
           ^^^^^^^^^^^^^^^^^^^^^^^^^^^^^^
  File "/Users/muhammedsaeed/anaconda3/envs/KB/lib/python3.11/site-packages/requests/sessions.py", line 746, in send
    r.content
  File "/Users/muhammedsaeed/anaconda3/envs/KB/lib/python3.11/site-packages/requests/models.py", line 902, in content
    self._content = b"".join(self.iter_content(CONTENT_CHUNK_SIZE)) or b""
                    ^^^^^^^^^^^^^^^^^^^^^^^^^^^^^^^^^^^^^^^^^^^^^^^
  File "/Users/muhammedsaeed/anaconda3/envs/KB/lib/python3.11/site-packages/requests/models.py", line 826, in generate
    raise ConnectionError(e)
requests.exceptions.ConnectionError: HTTPSConnectionPool(host='api.deepseek.com', port=443): Read timed out.

